{"links": {"self": {"href": "data/repositories/ignitionrobotics/ign-transport/issues/113/comments/53911389.json"}, "html": {"href": "#!/ignitionrobotics/ign-transport/issues/113#comment-53911389"}}, "issue": {"links": {"self": {"href": "data/repositories/ignitionrobotics/ign-transport/issues/113.json"}}, "type": "issue", "id": 113, "repository": {"links": {"self": {"href": "data/repositories/ignitionrobotics/ign-transport.json"}, "html": {"href": "#!/ignitionrobotics/ign-transport"}, "avatar": {"href": "data/bytebucket.org/ravatar/{4249390a-7f55-404b-990d-817ba94cc7ac}ts=1533306"}}, "type": "repository", "name": "ign-transport", "full_name": "ignitionrobotics/ign-transport", "uuid": "{4249390a-7f55-404b-990d-817ba94cc7ac}"}, "title": "[Fedora KDE] Tests do not pass on fresh source install - Discovery fails"}, "content": {"raw": "Reproduced the error on Fedora KDE 30.", "markup": "markdown", "html": "<p>Reproduced the error on Fedora KDE 30.</p>", "type": "rendered"}, "created_on": "2019-09-15T14:44:19.759043+00:00", "user": {"display_name": "Til Hoff", "uuid": "{5b5196a3-571e-4e4c-bed3-6f72e4dabba8}", "links": {"self": {"href": "https://api.bitbucket.org/2.0/users/%7B5b5196a3-571e-4e4c-bed3-6f72e4dabba8%7D"}, "html": {"href": "https://bitbucket.org/%7B5b5196a3-571e-4e4c-bed3-6f72e4dabba8%7D/"}, "avatar": {"href": "data/secure.gravatar.com/avatar/1835281ac000de88eb0ed5f38cd82eaed=httpsavatar-management--avatars.us-west-2.prod.public.atl-paas.netinitialsTH-5.png"}}, "nickname": "turakar", "type": "user", "account_id": "557058:0928ff78-c705-4502-bf3b-52e34e5508f2"}, "updated_on": "2019-09-30T09:56:41.665492+00:00", "type": "issue_comment", "id": 53911389}