{"priority": "major", "kind": "bug", "repository": {"links": {"self": {"href": "data/repositories/ignitionrobotics/ign-transport.json"}, "html": {"href": "#!/ignitionrobotics/ign-transport"}, "avatar": {"href": "data/bytebucket.org/ravatar/{4249390a-7f55-404b-990d-817ba94cc7ac}ts=1533306"}}, "type": "repository", "name": "ign-transport", "full_name": "ignitionrobotics/ign-transport", "uuid": "{4249390a-7f55-404b-990d-817ba94cc7ac}"}, "links": {"attachments": {"href": "data/repositories/ignitionrobotics/ign-transport/issues/90/attachments_page=1.json"}, "self": {"href": "data/repositories/ignitionrobotics/ign-transport/issues/90.json"}, "watch": {"href": "https://api.bitbucket.org/2.0/repositories/ignitionrobotics/ign-transport/issues/90/watch"}, "comments": {"href": "data/repositories/ignitionrobotics/ign-transport/issues/90/comments_page=1.json"}, "html": {"href": "#!/ignitionrobotics/ign-transport/issues/90/spurious-crashes-from-the-ign-log-record"}, "vote": {"href": "https://api.bitbucket.org/2.0/repositories/ignitionrobotics/ign-transport/issues/90/vote"}}, "reporter": {"display_name": "Michael Grey", "uuid": "{c1cdfe52-2887-474c-ae99-72fdc53a59c9}", "links": {"self": {"href": "https://api.bitbucket.org/2.0/users/%7Bc1cdfe52-2887-474c-ae99-72fdc53a59c9%7D"}, "html": {"href": "https://bitbucket.org/%7Bc1cdfe52-2887-474c-ae99-72fdc53a59c9%7D/"}, "avatar": {"href": "https://avatar-management--avatars.us-west-2.prod.public.atl-paas.net/557058:67759e29-d1df-465f-868d-047738e36fc9/d42d74cf-c1bd-4431-8288-07f543bbe325/128"}}, "nickname": "mxgrey", "type": "user", "account_id": "557058:67759e29-d1df-465f-868d-047738e36fc9"}, "title": "Spurious crashes from the ign log record tool", "component": null, "votes": 0, "watches": 1, "content": {"raw": "I haven't been able to track down a cause yet, but I've been noticing spurious `std::bad_function_call` exceptions getting thrown while trying to use the `ign log record` tool. Similar spurious exceptions have been noticed in the unit testing, but it has been inconsistent and difficult to reproduce.\n\nSo far the crash has only happened to me before any topics have begun publishing, so maybe there's some undefined behavior when trying to record before anything has been published.", "markup": "markdown", "html": "<p>I haven't been able to track down a cause yet, but I've been noticing spurious <code>std::bad_function_call</code> exceptions getting thrown while trying to use the <code>ign log record</code> tool. Similar spurious exceptions have been noticed in the unit testing, but it has been inconsistent and difficult to reproduce.</p>\n<p>So far the crash has only happened to me before any topics have begun publishing, so maybe there's some undefined behavior when trying to record before anything has been published.</p>", "type": "rendered"}, "assignee": {"display_name": "Shane Loretz", "uuid": "{656e3311-aad9-45a1-aaf7-b0ee0e84b287}", "links": {"self": {"href": "https://api.bitbucket.org/2.0/users/%7B656e3311-aad9-45a1-aaf7-b0ee0e84b287%7D"}, "html": {"href": "https://bitbucket.org/%7B656e3311-aad9-45a1-aaf7-b0ee0e84b287%7D/"}, "avatar": {"href": "https://avatar-management--avatars.us-west-2.prod.public.atl-paas.net/557058:684383ab-ac95-4859-a350-4a6f41a94a22/c7a1ebf5-cade-4115-9f26-9d3facb776db/128"}}, "nickname": "Shane Loretz", "type": "user", "account_id": "557058:684383ab-ac95-4859-a350-4a6f41a94a22"}, "state": "resolved", "version": null, "edited_on": null, "created_on": "2018-05-09T01:03:21.721999+00:00", "milestone": null, "updated_on": "2018-06-13T22:09:22.089658+00:00", "type": "issue", "id": 90}